2025-07-24 17:23:14,940 INFO    StreamThr :3297814 [internal.py:wandb_internal():86] W&B internal server running at pid: 3297814, started at: 2025-07-24 17:23:14.938094
2025-07-24 17:23:14,960 DEBUG   HandlerThread:3297814 [handler.py:handle_request():146] handle_request: status
2025-07-24 17:23:14,966 INFO    WriterThread:3297814 [datastore.py:open_for_write():85] open: /home/rinya/ZOLLMFT/ZO_LLM/wandb/run-20250724_172314-dcr1o2zi/run-dcr1o2zi.wandb
2025-07-24 17:23:14,975 DEBUG   SenderThread:3297814 [sender.py:send():382] send: header
2025-07-24 17:23:14,976 DEBUG   SenderThread:3297814 [sender.py:send():382] send: run
2025-07-24 17:23:15,262 ERROR   SenderThread:3297814 [internal_api.py:execute():373] 403 response executing GraphQL.
2025-07-24 17:23:15,262 ERROR   SenderThread:3297814 [internal_api.py:execute():374] <!doctype html><meta charset="utf-8"><meta name=viewport content="width=device-width, initial-scale=1"><title>403</title>403 Forbidden
2025-07-24 17:23:15,262 ERROR   SenderThread:3297814 [sender.py:send_run():987] It appears that you do not have permission to access the requested resource. Please reach out to the project owner to grant you access. If you have the correct permissions, verify that there are no issues with your networking setup.(Error 403: Forbidden)
Traceback (most recent call last):
  File "/home/rinya/anaconda3/envs/zollm2/lib/python3.10/site-packages/wandb/sdk/lib/retry.py", line 131, in __call__
    result = self._call_fn(*args, **kwargs)
  File "/home/rinya/anaconda3/envs/zollm2/lib/python3.10/site-packages/wandb/sdk/internal/internal_api.py", line 369, in execute
    return self.client.execute(*args, **kwargs)  # type: ignore
  File "/home/rinya/anaconda3/envs/zollm2/lib/python3.10/site-packages/wandb/vendor/gql-0.2.0/wandb_gql/client.py", line 52, in execute
    result = self._get_result(document, *args, **kwargs)
  File "/home/rinya/anaconda3/envs/zollm2/lib/python3.10/site-packages/wandb/vendor/gql-0.2.0/wandb_gql/client.py", line 60, in _get_result
    return self.transport.execute(document, *args, **kwargs)
  File "/home/rinya/anaconda3/envs/zollm2/lib/python3.10/site-packages/wandb/sdk/lib/gql_request.py", line 59, in execute
    request.raise_for_status()
  File "/home/rinya/anaconda3/envs/zollm2/lib/python3.10/site-packages/requests/models.py", line 1026, in raise_for_status
    raise HTTPError(http_error_msg, response=self)
requests.exceptions.HTTPError: 403 Client Error: Forbidden for url: https://api.wandb.ai/graphql

During handling of the above exception, another exception occurred:

Traceback (most recent call last):
  File "/home/rinya/anaconda3/envs/zollm2/lib/python3.10/site-packages/wandb/sdk/internal/sender.py", line 985, in send_run
    self._init_run(run, config_value_dict)
  File "/home/rinya/anaconda3/envs/zollm2/lib/python3.10/site-packages/wandb/sdk/internal/sender.py", line 1027, in _init_run
    server_run, inserted, server_messages = self._api.upsert_run(
  File "/home/rinya/anaconda3/envs/zollm2/lib/python3.10/site-packages/wandb/apis/normalize.py", line 73, in wrapper
    raise err
  File "/home/rinya/anaconda3/envs/zollm2/lib/python3.10/site-packages/wandb/apis/normalize.py", line 41, in wrapper
    return func(*args, **kwargs)
  File "/home/rinya/anaconda3/envs/zollm2/lib/python3.10/site-packages/wandb/sdk/internal/internal_api.py", line 2155, in upsert_run
    self.server_settings_introspection()
  File "/home/rinya/anaconda3/envs/zollm2/lib/python3.10/site-packages/wandb/apis/normalize.py", line 73, in wrapper
    raise err
  File "/home/rinya/anaconda3/envs/zollm2/lib/python3.10/site-packages/wandb/apis/normalize.py", line 41, in wrapper
    return func(*args, **kwargs)
  File "/home/rinya/anaconda3/envs/zollm2/lib/python3.10/site-packages/wandb/sdk/internal/internal_api.py", line 585, in server_settings_introspection
    res = self.gql(query)
  File "/home/rinya/anaconda3/envs/zollm2/lib/python3.10/site-packages/wandb/sdk/internal/internal_api.py", line 341, in gql
    ret = self._retry_gql(
  File "/home/rinya/anaconda3/envs/zollm2/lib/python3.10/site-packages/wandb/sdk/lib/retry.py", line 147, in __call__
    retry_timedelta_triggered = check_retry_fn(e)
  File "/home/rinya/anaconda3/envs/zollm2/lib/python3.10/site-packages/wandb/util.py", line 907, in no_retry_auth
    raise CommError(
wandb.errors.CommError: It appears that you do not have permission to access the requested resource. Please reach out to the project owner to grant you access. If you have the correct permissions, verify that there are no issues with your networking setup.(Error 403: Forbidden)
2025-07-24 17:23:15,439 DEBUG   HandlerThread:3297814 [handler.py:handle_request():146] handle_request: shutdown
2025-07-24 17:23:15,439 INFO    HandlerThread:3297814 [handler.py:finish():866] shutting down handler
2025-07-24 17:23:15,967 INFO    WriterThread:3297814 [datastore.py:close():294] close: /home/rinya/ZOLLMFT/ZO_LLM/wandb/run-20250724_172314-dcr1o2zi/run-dcr1o2zi.wandb
2025-07-24 17:23:16,284 INFO    SenderThread:3297814 [sender.py:finish():1548] shutting down sender
